Unhandled exception in thread started by <function check_errors.<locals>.wrapper at 0x7fd4c5829bf8>
Traceback (most recent call last):
  File "/home/kzeery/CS1XA3/python_env/lib/python3.5/site-packages/django/utils/autoreload.py", line 225, in wrapper
    fn(*args, **kwargs)
  File "/home/kzeery/CS1XA3/python_env/lib/python3.5/site-packages/django/core/management/commands/runserver.py", line 117, in inner_run
    self.check(display_num_errors=True)
  File "/home/kzeery/CS1XA3/python_env/lib/python3.5/site-packages/django/core/management/base.py", line 379, in check
    include_deployment_checks=include_deployment_checks,
  File "/home/kzeery/CS1XA3/python_env/lib/python3.5/site-packages/django/core/management/base.py", line 366, in _run_checks
    return checks.run_checks(**kwargs)
  File "/home/kzeery/CS1XA3/python_env/lib/python3.5/site-packages/django/core/checks/registry.py", line 71, in run_checks
    new_errors = check(app_configs=app_configs)
  File "/home/kzeery/CS1XA3/python_env/lib/python3.5/site-packages/django/core/checks/urls.py", line 13, in check_url_config
    return check_resolver(resolver)
  File "/home/kzeery/CS1XA3/python_env/lib/python3.5/site-packages/django/core/checks/urls.py", line 23, in check_resolver
    return check_method()
  File "/home/kzeery/CS1XA3/python_env/lib/python3.5/site-packages/django/urls/resolvers.py", line 396, in check
    for pattern in self.url_patterns:
  File "/home/kzeery/CS1XA3/python_env/lib/python3.5/site-packages/django/utils/functional.py", line 37, in __get__
    res = instance.__dict__[self.name] = self.func(instance)
  File "/home/kzeery/CS1XA3/python_env/lib/python3.5/site-packages/django/urls/resolvers.py", line 533, in url_patterns
    patterns = getattr(self.urlconf_module, "urlpatterns", self.urlconf_module)
  File "/home/kzeery/CS1XA3/python_env/lib/python3.5/site-packages/django/utils/functional.py", line 37, in __get__
    res = instance.__dict__[self.name] = self.func(instance)
  File "/home/kzeery/CS1XA3/python_env/lib/python3.5/site-packages/django/urls/resolvers.py", line 526, in urlconf_module
    return import_module(self.urlconf_name)
  File "/usr/lib/python3.5/importlib/__init__.py", line 126, in import_module
    return _bootstrap._gcd_import(name[level:], package, level)
  File "<frozen importlib._bootstrap>", line 986, in _gcd_import
  File "<frozen importlib._bootstrap>", line 969, in _find_and_load
  File "<frozen importlib._bootstrap>", line 958, in _find_and_load_unlocked
  File "<frozen importlib._bootstrap>", line 673, in _load_unlocked
  File "<frozen importlib._bootstrap_external>", line 665, in exec_module
  File "<frozen importlib._bootstrap>", line 222, in _call_with_frames_removed
  File "/home/kzeery/CS1XA3/python_env/django_project/django_project/urls.py", line 22, in <module>
    path('e/kzeery/', include('Helloapp.urls')),
NameError: name 'include' is not defined
Performing system checks...

[12/Mar/2019 16:07:00] "GET /e/kzeery/ HTTP/1.1" 200 37
[12/Mar/2019 16:07:45] "GET /e/kzeery/ HTTP/1.1" 200 37
